<?xml version="1.0" ?>
<robot name = "alpha_bot">
	

	<!--==========Macros===================-->


	<!--============Material==========-->
	
	<material name="blue">
    	<color rgba="0 0 0.8 2"/>
  	</material>

	<material name="grey">
   		<color rgba="0.5 0.5 0.5 2"/>
 	</material>

	<material name="red">
    	<color rgba="1 0 0 2"/>
	</material>
	
	<material name="green">
    	<color rgba="0 1 0 2"/>
	</material>

	<material name="white">
    	<color rgba="1 1 1 2"/>
	</material>

	<material name="black">
    	<color rgba="0 0 0 2"/>
	</material>
	
	
	<!--===========links==============-->
	
	<!--==============================-->
	<link name="base_link">
		<inertial>
			<mass value="10" />		
			<inertia ixx="1" iyy="1" izz="1" ixy="0" ixz="0" iyz="0"/>
		</inertial>		
		<visual>
			<geometry>
				<box size="0.2 0.24 .01	"/>
			</geometry>
			<origin xyz="0 0 0.1"/>
			<material name="black"/>
		</visual>		
		<collision>
			<geometry>
				<box size="0.2 0.24 0.01"/>
			</geometry>		
			<origin xyz="0 0 0.1"/>
		</collision>			
	
	</link>
	
	<!--==============================-->	
	<link name="right_leg">
		<inertial>
			<mass value="1" />		
			<inertia ixx="1" iyy="1" izz="1" ixy="0" ixz="0" iyz="0"/>
		</inertial>			
		<visual>
			<geometry>
				<box size="0.005 0.04 .09	"/>
			</geometry>
			<origin xyz="0 0 0"/>
			<material name="blue"/>
		</visual>		
		<collision>
			<geometry>
				<box size="0.005 0.04 0.09"/>
			</geometry>		
			<origin xyz="0 0 0"/>
		</collision>	
	</link>
	
	<!--==============================-->	
	<link name="left_leg">
		<inertial>
			<mass value="1" />		
			<inertia ixx="1" iyy="1" izz="1" ixy="0" ixz="0" iyz="0"/>
		</inertial>		
		<visual>
			<geometry>
				<box size="0.005 0.04 .09	"/>
			</geometry>
			<origin xyz="0 0 0"/>
			<material name="blue"/>
		</visual>		
		<collision>
			<geometry>
				<box size="0.005 0.04 0.09"/>
			</geometry>		
			<origin xyz="0 0 0"/>
		</collision>
	</link>
	
	<!--==============================-->	
	<link name="right_wheel">
		<inertial>
			<mass value="1" />		
			<inertia ixx="1" iyy="1" izz="1" ixy="0" ixz="0" iyz="0"/>
		</inertial>
		
		<visual>gazebo tutorial
			<geometry>
				<cylinder radius="0.035" length="0.01"/>
			</geometry>
			<material name="grey"/>
		</visual>
		
		<collision>
			<geometry>
				<cylinder radius="0.035" length="0.01"/>
			</geometry>
		</collision>
	
	</link>
	
	<!--==============================-->	
	<link name="left_wheel">
		<inertial>
			<mass value="1" />		
			<inertia ixx="1" iyy="1" izz="1" ixy="0" ixz="0" iyz="0"/>
		</inertial>
		
		<visual>
			<geometry>
				<cylinder radius="0.035" length="0.01"/>
			</geometry>
			<material name="grey"/>
		</visual>
		
		<collision>
			<geometry>
				<cylinder radius="0.035" length="0.01"/>
			</geometry>
		</collision>
	
	</link>
	
	<!--==============================-->	
	<link name="caster_leg">
		<inertial>
			<mass value="1" />		
			<inertia ixx="1" iyy="1" izz="1" ixy="0" ixz="0" iyz="0"/>
		</inertial>		
		
		<visual>
			<geometry>
				<box size="0.04 0.04 .1	"/>
			</geometry>
			<origin xyz="0 0 0"/>
			<material name="green"/>
		</visual>		
		
		<collision>
			<geometry>
				<box size="0.04 0.04 0.1"/>
			</geometry>		
			<origin xyz="0 0 0"/>
		</collision>
	
	</link>
	
	<!--==============================-->	
	<link name="caster_wheel">
		<inertial>
			<mass value="1" />		
			<inertia ixx="1" iyy="1" izz="1" ixy="0" ixz="0" iyz="0"/>
		</inertial>
		
		<visual>
			<material name="red"/>
			<geometry>
				<sphere radius="0.005"/>
			</geometry>
		</visual>
		
		<collision>
			<geometry>
				<sphere radius="0.005"/>
			</geometry>
		</collision>
			
	</link>
	


	<!--============Joints==================-->


	<joint name="right_leg_joint" type="fixed">
		<parent link="base_link"/>
		<child link="right_leg"/>
		<origin xyz="0.1 0.1 0.06" rpy="0 0 0" />
	</joint>

	<joint name="left_leg_joint" type="fixed">
		<parent link="base_link"/>
		<child link="left_leg"/>
		<origin xyz="-0.1 0.1 0.06" rpy="0 0 0"/>
	</joint>

	<joint name="caster_leg_joint" type="fixed">
		<parent link="base_link"/>
		<child link="caster_leg"/>
		<origin xyz="0 -0.1 0.055" rpy="0 0 0"/>		
	</joint>

	<joint name="right_wheel_joint" type="continuous">
		<parent link="right_leg"/>
		<child link="right_wheel"/>
		<origin xyz="0.0075 0 -0.03" rpy="0 1.57 0"/>
		<axis xyz="0 0 1"/>
		<limit effort="30" velocity="1.0"/>
	</joint>

	<joint name="left_wheel_joint" type="continuous">
		<parent link="left_leg"/>
		<child link="left_wheel"/>
		<origin xyz="-0.0075 0 -0.03" rpy="0 1.57 0"/>
		<axis xyz="0 0 1"/>
		<limit effort="30" velocity="1.0"/>
	</joint>

	<joint name="caster_wheel_joint" type="fixed">
		<parent link="caster_leg"/>
		<child link="caster_wheel"/>
		<origin xyz="0 0 -0.05" rpy="0 0 0"/>
	</joint>
	
	<!-- gazebo_plugin for arm -->
	<gazebo>
    	<plugin name="gazebo_ros_control" filename="libgazebo_ros_control.so">
   		<namespace>/</namespace>
   		</plugin>
	</gazebo>
	
	<!-- ======Physical properties===========-->
	
	<gazebo reference="right_wheel">
		<mu1 value="20.0"/>
		<mu2 value="10.0"/>
		<kp value="1000000.0"/>
		<kd value="1.0"/>
		<material>Gazebo/Grey</material>
	</gazebo>
	
	<gazebo reference="left_wheel">
		<mu1 value="20.0"/>
		<mu2 value="10.0"/>
		<kp value="1000000.0"/>
		<kd value="1.0"/>
		<material>Gazebo/Grey</material>
	</gazebo>
	
	<!-- ============Transmission============-->
	
	<transmission name="right_rotate_trans">
		<type>transmission_interface/SimpleTransmission</type>
		<actuator name="$right_rotate_motor">
			<mechanicalReduction>1</mechanicalReduction>
		</actuator>
		<joint name="right_wheel_joint">
			<hardwareInterface>VelocityJointInterface</hardwareInterface>
		</joint>
	</transmission>
	
	<transmission name="left_rotate_trans">
		<type>transmission_interface/SimpleTransmission</type>
		<actuator name="$left_rotate_motor">
			<mechanicalReduction>1</mechanicalReduction>
		</actuator>
		<joint name="left_wheel_joint">
			<hardwareInterface>VelocityJointInterface</hardwareInterface>
		</joint>
	</transmission>
	

</robot>
